<?xml version="1.0"?><robot name="pepe">
	<link name="0">
		<visual>
			<geometry>
				<cylinder length="1.9998" radius="0.20443396002244985"/>
			</geometry>
		</visual>
		<collision>
			<geometry>
				<cylinder length="1.9998" radius="0.20443396002244985"/>
			</geometry>
		</collision>
		<inertial>
			<mass value="0.2625684372362268"/>
			<inertia ixx="0.03" iyy="0.03" izz="0.03" ixy="0" ixz="0" iyx="0"/>
		</inertial>
	</link>
	<link name="11">
		<visual>
			<geometry>
				<cylinder length="1.9998" radius="0.7063905792152048"/>
			</geometry>
		</visual>
		<collision>
			<geometry>
				<cylinder length="1.9998" radius="0.7063905792152048"/>
			</geometry>
		</collision>
		<inertial>
			<mass value="3.134918350295081"/>
			<inertia ixx="0.03" iyy="0.03" izz="0.03" ixy="0" ixz="0" iyx="0"/>
		</inertial>
	</link>
	<link name="22">
		<visual>
			<geometry>
				<cylinder length="0.3264363445720478" radius="0.9999"/>
			</geometry>
		</visual>
		<collision>
			<geometry>
				<cylinder length="0.3264363445720478" radius="0.9999"/>
			</geometry>
		</collision>
		<inertial>
			<mass value="1.0253249262231574"/>
			<inertia ixx="0.03" iyy="0.03" izz="0.03" ixy="0" ixz="0" iyx="0"/>
		</inertial>
	</link>
	<link name="23">
		<visual>
			<geometry>
				<cylinder length="0.3264363445720478" radius="0.9999"/>
			</geometry>
		</visual>
		<collision>
			<geometry>
				<cylinder length="0.3264363445720478" radius="0.9999"/>
			</geometry>
		</collision>
		<inertial>
			<mass value="1.0253249262231574"/>
			<inertia ixx="0.03" iyy="0.03" izz="0.03" ixy="0" ixz="0" iyx="0"/>
		</inertial>
	</link>
	<link name="24">
		<visual>
			<geometry>
				<cylinder length="0.3264363445720478" radius="0.9999"/>
			</geometry>
		</visual>
		<collision>
			<geometry>
				<cylinder length="0.3264363445720478" radius="0.9999"/>
			</geometry>
		</collision>
		<inertial>
			<mass value="1.0253249262231574"/>
			<inertia ixx="0.03" iyy="0.03" izz="0.03" ixy="0" ixz="0" iyx="0"/>
		</inertial>
	</link>
	<link name="35">
		<visual>
			<geometry>
				<cylinder length="0.34569771785372927" radius="0.9999"/>
			</geometry>
		</visual>
		<collision>
			<geometry>
				<cylinder length="0.34569771785372927" radius="0.9999"/>
			</geometry>
		</collision>
		<inertial>
			<mass value="1.0858242133502927"/>
			<inertia ixx="0.03" iyy="0.03" izz="0.03" ixy="0" ixz="0" iyx="0"/>
		</inertial>
	</link>
	<link name="46">
		<visual>
			<geometry>
				<cylinder length="1.1639648500576785" radius="0.9566205217931367"/>
			</geometry>
		</visual>
		<collision>
			<geometry>
				<cylinder length="1.1639648500576785" radius="0.9566205217931367"/>
			</geometry>
		</collision>
		<inertial>
			<mass value="3.3463327573548867"/>
			<inertia ixx="0.03" iyy="0.03" izz="0.03" ixy="0" ixz="0" iyx="0"/>
		</inertial>
	</link>
	<link name="47">
		<visual>
			<geometry>
				<cylinder length="1.1639648500576785" radius="0.9566205217931367"/>
			</geometry>
		</visual>
		<collision>
			<geometry>
				<cylinder length="1.1639648500576785" radius="0.9566205217931367"/>
			</geometry>
		</collision>
		<inertial>
			<mass value="3.3463327573548867"/>
			<inertia ixx="0.03" iyy="0.03" izz="0.03" ixy="0" ixz="0" iyx="0"/>
		</inertial>
	</link>
	<link name="48">
		<visual>
			<geometry>
				<cylinder length="1.1639648500576785" radius="0.9566205217931367"/>
			</geometry>
		</visual>
		<collision>
			<geometry>
				<cylinder length="1.1639648500576785" radius="0.9566205217931367"/>
			</geometry>
		</collision>
		<inertial>
			<mass value="3.3463327573548867"/>
			<inertia ixx="0.03" iyy="0.03" izz="0.03" ixy="0" ixz="0" iyx="0"/>
		</inertial>
	</link>
	<link name="39">
		<visual>
			<geometry>
				<cylinder length="0.34569771785372927" radius="0.9999"/>
			</geometry>
		</visual>
		<collision>
			<geometry>
				<cylinder length="0.34569771785372927" radius="0.9999"/>
			</geometry>
		</collision>
		<inertial>
			<mass value="1.0858242133502927"/>
			<inertia ixx="0.03" iyy="0.03" izz="0.03" ixy="0" ixz="0" iyx="0"/>
		</inertial>
	</link>
	<link name="410">
		<visual>
			<geometry>
				<cylinder length="1.1639648500576785" radius="0.9566205217931367"/>
			</geometry>
		</visual>
		<collision>
			<geometry>
				<cylinder length="1.1639648500576785" radius="0.9566205217931367"/>
			</geometry>
		</collision>
		<inertial>
			<mass value="3.3463327573548867"/>
			<inertia ixx="0.03" iyy="0.03" izz="0.03" ixy="0" ixz="0" iyx="0"/>
		</inertial>
	</link>
	<link name="411">
		<visual>
			<geometry>
				<cylinder length="1.1639648500576785" radius="0.9566205217931367"/>
			</geometry>
		</visual>
		<collision>
			<geometry>
				<cylinder length="1.1639648500576785" radius="0.9566205217931367"/>
			</geometry>
		</collision>
		<inertial>
			<mass value="3.3463327573548867"/>
			<inertia ixx="0.03" iyy="0.03" izz="0.03" ixy="0" ixz="0" iyx="0"/>
		</inertial>
	</link>
	<link name="412">
		<visual>
			<geometry>
				<cylinder length="1.1639648500576785" radius="0.9566205217931367"/>
			</geometry>
		</visual>
		<collision>
			<geometry>
				<cylinder length="1.1639648500576785" radius="0.9566205217931367"/>
			</geometry>
		</collision>
		<inertial>
			<mass value="3.3463327573548867"/>
			<inertia ixx="0.03" iyy="0.03" izz="0.03" ixy="0" ixz="0" iyx="0"/>
		</inertial>
	</link>
	<link name="313">
		<visual>
			<geometry>
				<cylinder length="0.34569771785372927" radius="0.9999"/>
			</geometry>
		</visual>
		<collision>
			<geometry>
				<cylinder length="0.34569771785372927" radius="0.9999"/>
			</geometry>
		</collision>
		<inertial>
			<mass value="1.0858242133502927"/>
			<inertia ixx="0.03" iyy="0.03" izz="0.03" ixy="0" ixz="0" iyx="0"/>
		</inertial>
	</link>
	<link name="414">
		<visual>
			<geometry>
				<cylinder length="1.1639648500576785" radius="0.9566205217931367"/>
			</geometry>
		</visual>
		<collision>
			<geometry>
				<cylinder length="1.1639648500576785" radius="0.9566205217931367"/>
			</geometry>
		</collision>
		<inertial>
			<mass value="3.3463327573548867"/>
			<inertia ixx="0.03" iyy="0.03" izz="0.03" ixy="0" ixz="0" iyx="0"/>
		</inertial>
	</link>
	<link name="415">
		<visual>
			<geometry>
				<cylinder length="1.1639648500576785" radius="0.9566205217931367"/>
			</geometry>
		</visual>
		<collision>
			<geometry>
				<cylinder length="1.1639648500576785" radius="0.9566205217931367"/>
			</geometry>
		</collision>
		<inertial>
			<mass value="3.3463327573548867"/>
			<inertia ixx="0.03" iyy="0.03" izz="0.03" ixy="0" ixz="0" iyx="0"/>
		</inertial>
	</link>
	<link name="416">
		<visual>
			<geometry>
				<cylinder length="1.1639648500576785" radius="0.9566205217931367"/>
			</geometry>
		</visual>
		<collision>
			<geometry>
				<cylinder length="1.1639648500576785" radius="0.9566205217931367"/>
			</geometry>
		</collision>
		<inertial>
			<mass value="3.3463327573548867"/>
			<inertia ixx="0.03" iyy="0.03" izz="0.03" ixy="0" ixz="0" iyx="0"/>
		</inertial>
	</link>
	<link name="117">
		<visual>
			<geometry>
				<cylinder length="1.9998" radius="0.7063905792152048"/>
			</geometry>
		</visual>
		<collision>
			<geometry>
				<cylinder length="1.9998" radius="0.7063905792152048"/>
			</geometry>
		</collision>
		<inertial>
			<mass value="3.134918350295081"/>
			<inertia ixx="0.03" iyy="0.03" izz="0.03" ixy="0" ixz="0" iyx="0"/>
		</inertial>
	</link>
	<link name="218">
		<visual>
			<geometry>
				<cylinder length="0.3264363445720478" radius="0.9999"/>
			</geometry>
		</visual>
		<collision>
			<geometry>
				<cylinder length="0.3264363445720478" radius="0.9999"/>
			</geometry>
		</collision>
		<inertial>
			<mass value="1.0253249262231574"/>
			<inertia ixx="0.03" iyy="0.03" izz="0.03" ixy="0" ixz="0" iyx="0"/>
		</inertial>
	</link>
	<link name="219">
		<visual>
			<geometry>
				<cylinder length="0.3264363445720478" radius="0.9999"/>
			</geometry>
		</visual>
		<collision>
			<geometry>
				<cylinder length="0.3264363445720478" radius="0.9999"/>
			</geometry>
		</collision>
		<inertial>
			<mass value="1.0253249262231574"/>
			<inertia ixx="0.03" iyy="0.03" izz="0.03" ixy="0" ixz="0" iyx="0"/>
		</inertial>
	</link>
	<link name="220">
		<visual>
			<geometry>
				<cylinder length="0.3264363445720478" radius="0.9999"/>
			</geometry>
		</visual>
		<collision>
			<geometry>
				<cylinder length="0.3264363445720478" radius="0.9999"/>
			</geometry>
		</collision>
		<inertial>
			<mass value="1.0253249262231574"/>
			<inertia ixx="0.03" iyy="0.03" izz="0.03" ixy="0" ixz="0" iyx="0"/>
		</inertial>
	</link>
	<link name="321">
		<visual>
			<geometry>
				<cylinder length="0.34569771785372927" radius="0.9999"/>
			</geometry>
		</visual>
		<collision>
			<geometry>
				<cylinder length="0.34569771785372927" radius="0.9999"/>
			</geometry>
		</collision>
		<inertial>
			<mass value="1.0858242133502927"/>
			<inertia ixx="0.03" iyy="0.03" izz="0.03" ixy="0" ixz="0" iyx="0"/>
		</inertial>
	</link>
	<link name="422">
		<visual>
			<geometry>
				<cylinder length="1.1639648500576785" radius="0.9566205217931367"/>
			</geometry>
		</visual>
		<collision>
			<geometry>
				<cylinder length="1.1639648500576785" radius="0.9566205217931367"/>
			</geometry>
		</collision>
		<inertial>
			<mass value="3.3463327573548867"/>
			<inertia ixx="0.03" iyy="0.03" izz="0.03" ixy="0" ixz="0" iyx="0"/>
		</inertial>
	</link>
	<link name="423">
		<visual>
			<geometry>
				<cylinder length="1.1639648500576785" radius="0.9566205217931367"/>
			</geometry>
		</visual>
		<collision>
			<geometry>
				<cylinder length="1.1639648500576785" radius="0.9566205217931367"/>
			</geometry>
		</collision>
		<inertial>
			<mass value="3.3463327573548867"/>
			<inertia ixx="0.03" iyy="0.03" izz="0.03" ixy="0" ixz="0" iyx="0"/>
		</inertial>
	</link>
	<link name="424">
		<visual>
			<geometry>
				<cylinder length="1.1639648500576785" radius="0.9566205217931367"/>
			</geometry>
		</visual>
		<collision>
			<geometry>
				<cylinder length="1.1639648500576785" radius="0.9566205217931367"/>
			</geometry>
		</collision>
		<inertial>
			<mass value="3.3463327573548867"/>
			<inertia ixx="0.03" iyy="0.03" izz="0.03" ixy="0" ixz="0" iyx="0"/>
		</inertial>
	</link>
	<link name="325">
		<visual>
			<geometry>
				<cylinder length="0.34569771785372927" radius="0.9999"/>
			</geometry>
		</visual>
		<collision>
			<geometry>
				<cylinder length="0.34569771785372927" radius="0.9999"/>
			</geometry>
		</collision>
		<inertial>
			<mass value="1.0858242133502927"/>
			<inertia ixx="0.03" iyy="0.03" izz="0.03" ixy="0" ixz="0" iyx="0"/>
		</inertial>
	</link>
	<link name="426">
		<visual>
			<geometry>
				<cylinder length="1.1639648500576785" radius="0.9566205217931367"/>
			</geometry>
		</visual>
		<collision>
			<geometry>
				<cylinder length="1.1639648500576785" radius="0.9566205217931367"/>
			</geometry>
		</collision>
		<inertial>
			<mass value="3.3463327573548867"/>
			<inertia ixx="0.03" iyy="0.03" izz="0.03" ixy="0" ixz="0" iyx="0"/>
		</inertial>
	</link>
	<link name="427">
		<visual>
			<geometry>
				<cylinder length="1.1639648500576785" radius="0.9566205217931367"/>
			</geometry>
		</visual>
		<collision>
			<geometry>
				<cylinder length="1.1639648500576785" radius="0.9566205217931367"/>
			</geometry>
		</collision>
		<inertial>
			<mass value="3.3463327573548867"/>
			<inertia ixx="0.03" iyy="0.03" izz="0.03" ixy="0" ixz="0" iyx="0"/>
		</inertial>
	</link>
	<link name="428">
		<visual>
			<geometry>
				<cylinder length="1.1639648500576785" radius="0.9566205217931367"/>
			</geometry>
		</visual>
		<collision>
			<geometry>
				<cylinder length="1.1639648500576785" radius="0.9566205217931367"/>
			</geometry>
		</collision>
		<inertial>
			<mass value="3.3463327573548867"/>
			<inertia ixx="0.03" iyy="0.03" izz="0.03" ixy="0" ixz="0" iyx="0"/>
		</inertial>
	</link>
	<link name="329">
		<visual>
			<geometry>
				<cylinder length="0.34569771785372927" radius="0.9999"/>
			</geometry>
		</visual>
		<collision>
			<geometry>
				<cylinder length="0.34569771785372927" radius="0.9999"/>
			</geometry>
		</collision>
		<inertial>
			<mass value="1.0858242133502927"/>
			<inertia ixx="0.03" iyy="0.03" izz="0.03" ixy="0" ixz="0" iyx="0"/>
		</inertial>
	</link>
	<link name="430">
		<visual>
			<geometry>
				<cylinder length="1.1639648500576785" radius="0.9566205217931367"/>
			</geometry>
		</visual>
		<collision>
			<geometry>
				<cylinder length="1.1639648500576785" radius="0.9566205217931367"/>
			</geometry>
		</collision>
		<inertial>
			<mass value="3.3463327573548867"/>
			<inertia ixx="0.03" iyy="0.03" izz="0.03" ixy="0" ixz="0" iyx="0"/>
		</inertial>
	</link>
	<link name="431">
		<visual>
			<geometry>
				<cylinder length="1.1639648500576785" radius="0.9566205217931367"/>
			</geometry>
		</visual>
		<collision>
			<geometry>
				<cylinder length="1.1639648500576785" radius="0.9566205217931367"/>
			</geometry>
		</collision>
		<inertial>
			<mass value="3.3463327573548867"/>
			<inertia ixx="0.03" iyy="0.03" izz="0.03" ixy="0" ixz="0" iyx="0"/>
		</inertial>
	</link>
	<link name="432">
		<visual>
			<geometry>
				<cylinder length="1.1639648500576785" radius="0.9566205217931367"/>
			</geometry>
		</visual>
		<collision>
			<geometry>
				<cylinder length="1.1639648500576785" radius="0.9566205217931367"/>
			</geometry>
		</collision>
		<inertial>
			<mass value="3.3463327573548867"/>
			<inertia ixx="0.03" iyy="0.03" izz="0.03" ixy="0" ixz="0" iyx="0"/>
		</inertial>
	</link>
	<link name="133">
		<visual>
			<geometry>
				<cylinder length="1.9998" radius="0.7063905792152048"/>
			</geometry>
		</visual>
		<collision>
			<geometry>
				<cylinder length="1.9998" radius="0.7063905792152048"/>
			</geometry>
		</collision>
		<inertial>
			<mass value="3.134918350295081"/>
			<inertia ixx="0.03" iyy="0.03" izz="0.03" ixy="0" ixz="0" iyx="0"/>
		</inertial>
	</link>
	<link name="234">
		<visual>
			<geometry>
				<cylinder length="0.3264363445720478" radius="0.9999"/>
			</geometry>
		</visual>
		<collision>
			<geometry>
				<cylinder length="0.3264363445720478" radius="0.9999"/>
			</geometry>
		</collision>
		<inertial>
			<mass value="1.0253249262231574"/>
			<inertia ixx="0.03" iyy="0.03" izz="0.03" ixy="0" ixz="0" iyx="0"/>
		</inertial>
	</link>
	<link name="235">
		<visual>
			<geometry>
				<cylinder length="0.3264363445720478" radius="0.9999"/>
			</geometry>
		</visual>
		<collision>
			<geometry>
				<cylinder length="0.3264363445720478" radius="0.9999"/>
			</geometry>
		</collision>
		<inertial>
			<mass value="1.0253249262231574"/>
			<inertia ixx="0.03" iyy="0.03" izz="0.03" ixy="0" ixz="0" iyx="0"/>
		</inertial>
	</link>
	<link name="236">
		<visual>
			<geometry>
				<cylinder length="0.3264363445720478" radius="0.9999"/>
			</geometry>
		</visual>
		<collision>
			<geometry>
				<cylinder length="0.3264363445720478" radius="0.9999"/>
			</geometry>
		</collision>
		<inertial>
			<mass value="1.0253249262231574"/>
			<inertia ixx="0.03" iyy="0.03" izz="0.03" ixy="0" ixz="0" iyx="0"/>
		</inertial>
	</link>
	<link name="337">
		<visual>
			<geometry>
				<cylinder length="0.34569771785372927" radius="0.9999"/>
			</geometry>
		</visual>
		<collision>
			<geometry>
				<cylinder length="0.34569771785372927" radius="0.9999"/>
			</geometry>
		</collision>
		<inertial>
			<mass value="1.0858242133502927"/>
			<inertia ixx="0.03" iyy="0.03" izz="0.03" ixy="0" ixz="0" iyx="0"/>
		</inertial>
	</link>
	<link name="438">
		<visual>
			<geometry>
				<cylinder length="1.1639648500576785" radius="0.9566205217931367"/>
			</geometry>
		</visual>
		<collision>
			<geometry>
				<cylinder length="1.1639648500576785" radius="0.9566205217931367"/>
			</geometry>
		</collision>
		<inertial>
			<mass value="3.3463327573548867"/>
			<inertia ixx="0.03" iyy="0.03" izz="0.03" ixy="0" ixz="0" iyx="0"/>
		</inertial>
	</link>
	<link name="439">
		<visual>
			<geometry>
				<cylinder length="1.1639648500576785" radius="0.9566205217931367"/>
			</geometry>
		</visual>
		<collision>
			<geometry>
				<cylinder length="1.1639648500576785" radius="0.9566205217931367"/>
			</geometry>
		</collision>
		<inertial>
			<mass value="3.3463327573548867"/>
			<inertia ixx="0.03" iyy="0.03" izz="0.03" ixy="0" ixz="0" iyx="0"/>
		</inertial>
	</link>
	<link name="440">
		<visual>
			<geometry>
				<cylinder length="1.1639648500576785" radius="0.9566205217931367"/>
			</geometry>
		</visual>
		<collision>
			<geometry>
				<cylinder length="1.1639648500576785" radius="0.9566205217931367"/>
			</geometry>
		</collision>
		<inertial>
			<mass value="3.3463327573548867"/>
			<inertia ixx="0.03" iyy="0.03" izz="0.03" ixy="0" ixz="0" iyx="0"/>
		</inertial>
	</link>
	<link name="341">
		<visual>
			<geometry>
				<cylinder length="0.34569771785372927" radius="0.9999"/>
			</geometry>
		</visual>
		<collision>
			<geometry>
				<cylinder length="0.34569771785372927" radius="0.9999"/>
			</geometry>
		</collision>
		<inertial>
			<mass value="1.0858242133502927"/>
			<inertia ixx="0.03" iyy="0.03" izz="0.03" ixy="0" ixz="0" iyx="0"/>
		</inertial>
	</link>
	<link name="442">
		<visual>
			<geometry>
				<cylinder length="1.1639648500576785" radius="0.9566205217931367"/>
			</geometry>
		</visual>
		<collision>
			<geometry>
				<cylinder length="1.1639648500576785" radius="0.9566205217931367"/>
			</geometry>
		</collision>
		<inertial>
			<mass value="3.3463327573548867"/>
			<inertia ixx="0.03" iyy="0.03" izz="0.03" ixy="0" ixz="0" iyx="0"/>
		</inertial>
	</link>
	<link name="443">
		<visual>
			<geometry>
				<cylinder length="1.1639648500576785" radius="0.9566205217931367"/>
			</geometry>
		</visual>
		<collision>
			<geometry>
				<cylinder length="1.1639648500576785" radius="0.9566205217931367"/>
			</geometry>
		</collision>
		<inertial>
			<mass value="3.3463327573548867"/>
			<inertia ixx="0.03" iyy="0.03" izz="0.03" ixy="0" ixz="0" iyx="0"/>
		</inertial>
	</link>
	<link name="444">
		<visual>
			<geometry>
				<cylinder length="1.1639648500576785" radius="0.9566205217931367"/>
			</geometry>
		</visual>
		<collision>
			<geometry>
				<cylinder length="1.1639648500576785" radius="0.9566205217931367"/>
			</geometry>
		</collision>
		<inertial>
			<mass value="3.3463327573548867"/>
			<inertia ixx="0.03" iyy="0.03" izz="0.03" ixy="0" ixz="0" iyx="0"/>
		</inertial>
	</link>
	<link name="345">
		<visual>
			<geometry>
				<cylinder length="0.34569771785372927" radius="0.9999"/>
			</geometry>
		</visual>
		<collision>
			<geometry>
				<cylinder length="0.34569771785372927" radius="0.9999"/>
			</geometry>
		</collision>
		<inertial>
			<mass value="1.0858242133502927"/>
			<inertia ixx="0.03" iyy="0.03" izz="0.03" ixy="0" ixz="0" iyx="0"/>
		</inertial>
	</link>
	<link name="446">
		<visual>
			<geometry>
				<cylinder length="1.1639648500576785" radius="0.9566205217931367"/>
			</geometry>
		</visual>
		<collision>
			<geometry>
				<cylinder length="1.1639648500576785" radius="0.9566205217931367"/>
			</geometry>
		</collision>
		<inertial>
			<mass value="3.3463327573548867"/>
			<inertia ixx="0.03" iyy="0.03" izz="0.03" ixy="0" ixz="0" iyx="0"/>
		</inertial>
	</link>
	<link name="447">
		<visual>
			<geometry>
				<cylinder length="1.1639648500576785" radius="0.9566205217931367"/>
			</geometry>
		</visual>
		<collision>
			<geometry>
				<cylinder length="1.1639648500576785" radius="0.9566205217931367"/>
			</geometry>
		</collision>
		<inertial>
			<mass value="3.3463327573548867"/>
			<inertia ixx="0.03" iyy="0.03" izz="0.03" ixy="0" ixz="0" iyx="0"/>
		</inertial>
	</link>
	<link name="448">
		<visual>
			<geometry>
				<cylinder length="1.1639648500576785" radius="0.9566205217931367"/>
			</geometry>
		</visual>
		<collision>
			<geometry>
				<cylinder length="1.1639648500576785" radius="0.9566205217931367"/>
			</geometry>
		</collision>
		<inertial>
			<mass value="3.3463327573548867"/>
			<inertia ixx="0.03" iyy="0.03" izz="0.03" ixy="0" ixz="0" iyx="0"/>
		</inertial>
	</link>
	<joint name="11_to_0" type="revolute">
		<parent link="0"/>
		<child link="11"/>
		<axis xyz="0 1 0"/>
		<limit effort="1" upper="-3.1415" lower="3.1415" velocity="1"/>
		<origin rpy="12.565113977297736 5.333198344337363 0.0" xyz="0.03612401059642234 0.9999 0.8479822035926466"/>
	</joint>
	<joint name="22_to_11" type="revolute">
		<parent link="11"/>
		<child link="22"/>
		<axis xyz="0 1 0"/>
		<limit effort="1" upper="-3.1415" lower="3.1415" velocity="1"/>
		<origin rpy="12.565113977297736 1.2103636104120743 0.0" xyz="0.10325470855840346 0.44354800662050825 0.3369229968491583"/>
	</joint>
	<joint name="23_to_11" type="revolute">
		<parent link="11"/>
		<child link="23"/>
		<axis xyz="0 1 0"/>
		<limit effort="1" upper="-3.1415" lower="3.1415" velocity="1"/>
		<origin rpy="18.847670965946605 1.2103636104120743 0.0" xyz="0.10325470855840346 0.44354800662050825 0.3369229968491583"/>
	</joint>
	<joint name="24_to_11" type="revolute">
		<parent link="11"/>
		<child link="24"/>
		<axis xyz="0 1 0"/>
		<limit effort="1" upper="-3.1415" lower="3.1415" velocity="1"/>
		<origin rpy="25.130227954595473 1.2103636104120743 0.0" xyz="0.10325470855840346 0.44354800662050825 0.3369229968491583"/>
	</joint>
	<joint name="35_to_11" type="revolute">
		<parent link="11"/>
		<child link="35"/>
		<axis xyz="1 0 0"/>
		<limit effort="1" upper="-3.1415" lower="3.1415" velocity="1"/>
		<origin rpy="24.376707254128874 0.0 6.282556988648868" xyz="0.0 0.9999 0.40576930689114155"/>
	</joint>
	<joint name="46_to_35" type="revolute">
		<parent link="35"/>
		<child link="46"/>
		<axis xyz="1 0 0"/>
		<limit effort="1" upper="-3.1415" lower="3.1415" velocity="1"/>
		<origin rpy="12.565113977297736 0.7760470795366793 5.6703595050610085" xyz="0.10096680386422224 0.9999 0.7590477250910548"/>
	</joint>
	<joint name="47_to_35" type="revolute">
		<parent link="35"/>
		<child link="47"/>
		<axis xyz="1 0 0"/>
		<limit effort="1" upper="-3.1415" lower="3.1415" velocity="1"/>
		<origin rpy="18.847670965946605 0.7760470795366793 5.6703595050610085" xyz="0.10096680386422224 0.9999 0.7590477250910548"/>
	</joint>
	<joint name="48_to_35" type="revolute">
		<parent link="35"/>
		<child link="48"/>
		<axis xyz="1 0 0"/>
		<limit effort="1" upper="-3.1415" lower="3.1415" velocity="1"/>
		<origin rpy="25.130227954595473 0.7760470795366793 5.6703595050610085" xyz="0.10096680386422224 0.9999 0.7590477250910548"/>
	</joint>
	<joint name="39_to_11" type="revolute">
		<parent link="11"/>
		<child link="39"/>
		<axis xyz="1 0 0"/>
		<limit effort="1" upper="-3.1415" lower="3.1415" velocity="1"/>
		<origin rpy="29.252048704954646 0.0 6.282556988648868" xyz="0.0 0.9999 0.40576930689114155"/>
	</joint>
	<joint name="410_to_39" type="revolute">
		<parent link="39"/>
		<child link="410"/>
		<axis xyz="1 0 0"/>
		<limit effort="1" upper="-3.1415" lower="3.1415" velocity="1"/>
		<origin rpy="12.565113977297736 0.7760470795366793 5.6703595050610085" xyz="0.10096680386422224 0.9999 0.7590477250910548"/>
	</joint>
	<joint name="411_to_39" type="revolute">
		<parent link="39"/>
		<child link="411"/>
		<axis xyz="1 0 0"/>
		<limit effort="1" upper="-3.1415" lower="3.1415" velocity="1"/>
		<origin rpy="18.847670965946605 0.7760470795366793 5.6703595050610085" xyz="0.10096680386422224 0.9999 0.7590477250910548"/>
	</joint>
	<joint name="412_to_39" type="revolute">
		<parent link="39"/>
		<child link="412"/>
		<axis xyz="1 0 0"/>
		<limit effort="1" upper="-3.1415" lower="3.1415" velocity="1"/>
		<origin rpy="25.130227954595473 0.7760470795366793 5.6703595050610085" xyz="0.10096680386422224 0.9999 0.7590477250910548"/>
	</joint>
	<joint name="313_to_11" type="revolute">
		<parent link="11"/>
		<child link="313"/>
		<axis xyz="1 0 0"/>
		<limit effort="1" upper="-3.1415" lower="3.1415" velocity="1"/>
		<origin rpy="34.127390155780425 0.0 6.282556988648868" xyz="0.0 0.9999 0.40576930689114155"/>
	</joint>
	<joint name="414_to_313" type="revolute">
		<parent link="313"/>
		<child link="414"/>
		<axis xyz="1 0 0"/>
		<limit effort="1" upper="-3.1415" lower="3.1415" velocity="1"/>
		<origin rpy="12.565113977297736 0.7760470795366793 5.6703595050610085" xyz="0.10096680386422224 0.9999 0.7590477250910548"/>
	</joint>
	<joint name="415_to_313" type="revolute">
		<parent link="313"/>
		<child link="415"/>
		<axis xyz="1 0 0"/>
		<limit effort="1" upper="-3.1415" lower="3.1415" velocity="1"/>
		<origin rpy="18.847670965946605 0.7760470795366793 5.6703595050610085" xyz="0.10096680386422224 0.9999 0.7590477250910548"/>
	</joint>
	<joint name="416_to_313" type="revolute">
		<parent link="313"/>
		<child link="416"/>
		<axis xyz="1 0 0"/>
		<limit effort="1" upper="-3.1415" lower="3.1415" velocity="1"/>
		<origin rpy="25.130227954595473 0.7760470795366793 5.6703595050610085" xyz="0.10096680386422224 0.9999 0.7590477250910548"/>
	</joint>
	<joint name="117_to_0" type="revolute">
		<parent link="0"/>
		<child link="117"/>
		<axis xyz="0 1 0"/>
		<limit effort="1" upper="-3.1415" lower="3.1415" velocity="1"/>
		<origin rpy="18.847670965946605 5.333198344337363 0.0" xyz="0.03612401059642234 0.9999 0.8479822035926466"/>
	</joint>
	<joint name="218_to_117" type="revolute">
		<parent link="117"/>
		<child link="218"/>
		<axis xyz="0 1 0"/>
		<limit effort="1" upper="-3.1415" lower="3.1415" velocity="1"/>
		<origin rpy="12.565113977297736 1.2103636104120743 0.0" xyz="0.10325470855840346 0.44354800662050825 0.3369229968491583"/>
	</joint>
	<joint name="219_to_117" type="revolute">
		<parent link="117"/>
		<child link="219"/>
		<axis xyz="0 1 0"/>
		<limit effort="1" upper="-3.1415" lower="3.1415" velocity="1"/>
		<origin rpy="18.847670965946605 1.2103636104120743 0.0" xyz="0.10325470855840346 0.44354800662050825 0.3369229968491583"/>
	</joint>
	<joint name="220_to_117" type="revolute">
		<parent link="117"/>
		<child link="220"/>
		<axis xyz="0 1 0"/>
		<limit effort="1" upper="-3.1415" lower="3.1415" velocity="1"/>
		<origin rpy="25.130227954595473 1.2103636104120743 0.0" xyz="0.10325470855840346 0.44354800662050825 0.3369229968491583"/>
	</joint>
	<joint name="321_to_117" type="revolute">
		<parent link="117"/>
		<child link="321"/>
		<axis xyz="1 0 0"/>
		<limit effort="1" upper="-3.1415" lower="3.1415" velocity="1"/>
		<origin rpy="24.376707254128874 0.0 6.282556988648868" xyz="0.0 0.9999 0.40576930689114155"/>
	</joint>
	<joint name="422_to_321" type="revolute">
		<parent link="321"/>
		<child link="422"/>
		<axis xyz="1 0 0"/>
		<limit effort="1" upper="-3.1415" lower="3.1415" velocity="1"/>
		<origin rpy="12.565113977297736 0.7760470795366793 5.6703595050610085" xyz="0.10096680386422224 0.9999 0.7590477250910548"/>
	</joint>
	<joint name="423_to_321" type="revolute">
		<parent link="321"/>
		<child link="423"/>
		<axis xyz="1 0 0"/>
		<limit effort="1" upper="-3.1415" lower="3.1415" velocity="1"/>
		<origin rpy="18.847670965946605 0.7760470795366793 5.6703595050610085" xyz="0.10096680386422224 0.9999 0.7590477250910548"/>
	</joint>
	<joint name="424_to_321" type="revolute">
		<parent link="321"/>
		<child link="424"/>
		<axis xyz="1 0 0"/>
		<limit effort="1" upper="-3.1415" lower="3.1415" velocity="1"/>
		<origin rpy="25.130227954595473 0.7760470795366793 5.6703595050610085" xyz="0.10096680386422224 0.9999 0.7590477250910548"/>
	</joint>
	<joint name="325_to_117" type="revolute">
		<parent link="117"/>
		<child link="325"/>
		<axis xyz="1 0 0"/>
		<limit effort="1" upper="-3.1415" lower="3.1415" velocity="1"/>
		<origin rpy="29.252048704954646 0.0 6.282556988648868" xyz="0.0 0.9999 0.40576930689114155"/>
	</joint>
	<joint name="426_to_325" type="revolute">
		<parent link="325"/>
		<child link="426"/>
		<axis xyz="1 0 0"/>
		<limit effort="1" upper="-3.1415" lower="3.1415" velocity="1"/>
		<origin rpy="12.565113977297736 0.7760470795366793 5.6703595050610085" xyz="0.10096680386422224 0.9999 0.7590477250910548"/>
	</joint>
	<joint name="427_to_325" type="revolute">
		<parent link="325"/>
		<child link="427"/>
		<axis xyz="1 0 0"/>
		<limit effort="1" upper="-3.1415" lower="3.1415" velocity="1"/>
		<origin rpy="18.847670965946605 0.7760470795366793 5.6703595050610085" xyz="0.10096680386422224 0.9999 0.7590477250910548"/>
	</joint>
	<joint name="428_to_325" type="revolute">
		<parent link="325"/>
		<child link="428"/>
		<axis xyz="1 0 0"/>
		<limit effort="1" upper="-3.1415" lower="3.1415" velocity="1"/>
		<origin rpy="25.130227954595473 0.7760470795366793 5.6703595050610085" xyz="0.10096680386422224 0.9999 0.7590477250910548"/>
	</joint>
	<joint name="329_to_117" type="revolute">
		<parent link="117"/>
		<child link="329"/>
		<axis xyz="1 0 0"/>
		<limit effort="1" upper="-3.1415" lower="3.1415" velocity="1"/>
		<origin rpy="34.127390155780425 0.0 6.282556988648868" xyz="0.0 0.9999 0.40576930689114155"/>
	</joint>
	<joint name="430_to_329" type="revolute">
		<parent link="329"/>
		<child link="430"/>
		<axis xyz="1 0 0"/>
		<limit effort="1" upper="-3.1415" lower="3.1415" velocity="1"/>
		<origin rpy="12.565113977297736 0.7760470795366793 5.6703595050610085" xyz="0.10096680386422224 0.9999 0.7590477250910548"/>
	</joint>
	<joint name="431_to_329" type="revolute">
		<parent link="329"/>
		<child link="431"/>
		<axis xyz="1 0 0"/>
		<limit effort="1" upper="-3.1415" lower="3.1415" velocity="1"/>
		<origin rpy="18.847670965946605 0.7760470795366793 5.6703595050610085" xyz="0.10096680386422224 0.9999 0.7590477250910548"/>
	</joint>
	<joint name="432_to_329" type="revolute">
		<parent link="329"/>
		<child link="432"/>
		<axis xyz="1 0 0"/>
		<limit effort="1" upper="-3.1415" lower="3.1415" velocity="1"/>
		<origin rpy="25.130227954595473 0.7760470795366793 5.6703595050610085" xyz="0.10096680386422224 0.9999 0.7590477250910548"/>
	</joint>
	<joint name="133_to_0" type="revolute">
		<parent link="0"/>
		<child link="133"/>
		<axis xyz="0 1 0"/>
		<limit effort="1" upper="-3.1415" lower="3.1415" velocity="1"/>
		<origin rpy="25.130227954595473 5.333198344337363 0.0" xyz="0.03612401059642234 0.9999 0.8479822035926466"/>
	</joint>
	<joint name="234_to_133" type="revolute">
		<parent link="133"/>
		<child link="234"/>
		<axis xyz="0 1 0"/>
		<limit effort="1" upper="-3.1415" lower="3.1415" velocity="1"/>
		<origin rpy="12.565113977297736 1.2103636104120743 0.0" xyz="0.10325470855840346 0.44354800662050825 0.3369229968491583"/>
	</joint>
	<joint name="235_to_133" type="revolute">
		<parent link="133"/>
		<child link="235"/>
		<axis xyz="0 1 0"/>
		<limit effort="1" upper="-3.1415" lower="3.1415" velocity="1"/>
		<origin rpy="18.847670965946605 1.2103636104120743 0.0" xyz="0.10325470855840346 0.44354800662050825 0.3369229968491583"/>
	</joint>
	<joint name="236_to_133" type="revolute">
		<parent link="133"/>
		<child link="236"/>
		<axis xyz="0 1 0"/>
		<limit effort="1" upper="-3.1415" lower="3.1415" velocity="1"/>
		<origin rpy="25.130227954595473 1.2103636104120743 0.0" xyz="0.10325470855840346 0.44354800662050825 0.3369229968491583"/>
	</joint>
	<joint name="337_to_133" type="revolute">
		<parent link="133"/>
		<child link="337"/>
		<axis xyz="1 0 0"/>
		<limit effort="1" upper="-3.1415" lower="3.1415" velocity="1"/>
		<origin rpy="24.376707254128874 0.0 6.282556988648868" xyz="0.0 0.9999 0.40576930689114155"/>
	</joint>
	<joint name="438_to_337" type="revolute">
		<parent link="337"/>
		<child link="438"/>
		<axis xyz="1 0 0"/>
		<limit effort="1" upper="-3.1415" lower="3.1415" velocity="1"/>
		<origin rpy="12.565113977297736 0.7760470795366793 5.6703595050610085" xyz="0.10096680386422224 0.9999 0.7590477250910548"/>
	</joint>
	<joint name="439_to_337" type="revolute">
		<parent link="337"/>
		<child link="439"/>
		<axis xyz="1 0 0"/>
		<limit effort="1" upper="-3.1415" lower="3.1415" velocity="1"/>
		<origin rpy="18.847670965946605 0.7760470795366793 5.6703595050610085" xyz="0.10096680386422224 0.9999 0.7590477250910548"/>
	</joint>
	<joint name="440_to_337" type="revolute">
		<parent link="337"/>
		<child link="440"/>
		<axis xyz="1 0 0"/>
		<limit effort="1" upper="-3.1415" lower="3.1415" velocity="1"/>
		<origin rpy="25.130227954595473 0.7760470795366793 5.6703595050610085" xyz="0.10096680386422224 0.9999 0.7590477250910548"/>
	</joint>
	<joint name="341_to_133" type="revolute">
		<parent link="133"/>
		<child link="341"/>
		<axis xyz="1 0 0"/>
		<limit effort="1" upper="-3.1415" lower="3.1415" velocity="1"/>
		<origin rpy="29.252048704954646 0.0 6.282556988648868" xyz="0.0 0.9999 0.40576930689114155"/>
	</joint>
	<joint name="442_to_341" type="revolute">
		<parent link="341"/>
		<child link="442"/>
		<axis xyz="1 0 0"/>
		<limit effort="1" upper="-3.1415" lower="3.1415" velocity="1"/>
		<origin rpy="12.565113977297736 0.7760470795366793 5.6703595050610085" xyz="0.10096680386422224 0.9999 0.7590477250910548"/>
	</joint>
	<joint name="443_to_341" type="revolute">
		<parent link="341"/>
		<child link="443"/>
		<axis xyz="1 0 0"/>
		<limit effort="1" upper="-3.1415" lower="3.1415" velocity="1"/>
		<origin rpy="18.847670965946605 0.7760470795366793 5.6703595050610085" xyz="0.10096680386422224 0.9999 0.7590477250910548"/>
	</joint>
	<joint name="444_to_341" type="revolute">
		<parent link="341"/>
		<child link="444"/>
		<axis xyz="1 0 0"/>
		<limit effort="1" upper="-3.1415" lower="3.1415" velocity="1"/>
		<origin rpy="25.130227954595473 0.7760470795366793 5.6703595050610085" xyz="0.10096680386422224 0.9999 0.7590477250910548"/>
	</joint>
	<joint name="345_to_133" type="revolute">
		<parent link="133"/>
		<child link="345"/>
		<axis xyz="1 0 0"/>
		<limit effort="1" upper="-3.1415" lower="3.1415" velocity="1"/>
		<origin rpy="34.127390155780425 0.0 6.282556988648868" xyz="0.0 0.9999 0.40576930689114155"/>
	</joint>
	<joint name="446_to_345" type="revolute">
		<parent link="345"/>
		<child link="446"/>
		<axis xyz="1 0 0"/>
		<limit effort="1" upper="-3.1415" lower="3.1415" velocity="1"/>
		<origin rpy="12.565113977297736 0.7760470795366793 5.6703595050610085" xyz="0.10096680386422224 0.9999 0.7590477250910548"/>
	</joint>
	<joint name="447_to_345" type="revolute">
		<parent link="345"/>
		<child link="447"/>
		<axis xyz="1 0 0"/>
		<limit effort="1" upper="-3.1415" lower="3.1415" velocity="1"/>
		<origin rpy="18.847670965946605 0.7760470795366793 5.6703595050610085" xyz="0.10096680386422224 0.9999 0.7590477250910548"/>
	</joint>
	<joint name="448_to_345" type="revolute">
		<parent link="345"/>
		<child link="448"/>
		<axis xyz="1 0 0"/>
		<limit effort="1" upper="-3.1415" lower="3.1415" velocity="1"/>
		<origin rpy="25.130227954595473 0.7760470795366793 5.6703595050610085" xyz="0.10096680386422224 0.9999 0.7590477250910548"/>
	</joint>
</robot>
